Workbook
Name database1: Data!$A$1:$O$481
Name dia: Processing!$L$2:$L$59
Name Срез_Year: #N/A

Sheet DASHBOARD
B2: 🏠 DASHBOARD | V2: Cash Flow | Y2: Working Capital | AB2: Sales Transactions
B8: Sales management is a business discipline which is focused on the practical application of sales techniques and the management of a firm's sales operations. It is an important business function as net sales through the sale of products and services and resulting profit drive most commercial business. | L8: Sales Plan
L9: =Processing!H28 -> 0.80447325
B14: Income Breakdowns | D14: % | E14: Income
A16: • | B16: =Processing!E95 -> Data literacy | D16: =Processing!F95 -> 0.15049363 | E16: =Processing!G95 -> 530472
A17: • | B17: =Processing!E96 -> Data Science Soft | D17: =Processing!F96 -> 0.14123828 | E17: =Processing!G96 -> 497848
A18: • | B18: =Processing!E97 -> Parking places | D18: =Processing!F97 -> 0.089635959 | E18: =Processing!G97 -> 315956
A19: • | B19: =Processing!E98 -> Accounting Devices | D19: =Processing!F98 -> 0.089364744 | E19: =Processing!G98 -> 315000
A20: • | B20: =Processing!E99 -> Office rooms | D20: =Processing!F99 -> 0.088261728 | E20: =Processing!G99 -> 311112
A21: • | B21: =Processing!E100 -> Store | D21: =Processing!F100 -> 0.078549057 | E21: =Processing!G100 -> 276876
A22: • | B22: =Processing!E101 -> Data Visualization Soft | D22: =Processing!F101 -> 0.07493248 | E22: =Processing!G101 -> 264128
A23: • | B23: =Processing!E102 -> CRM Software | D23: =Processing!F102 -> 0.07035587 | E23: =Processing!G102 -> 247996
A24: • | B24: =Processing!E103 -> Asset Sale | D24: =Processing!F103 -> 0.06402374 | E24: =Processing!G103 -> 225676
A25: • | B25: =Processing!E104 -> Accounting Utilities | D25: =Processing!F104 -> 0.061465922 | E25: =Processing!G104 -> 216660
A26: • | B26: =Processing!E105 -> Visualization Modules | D26: =Processing!F105 -> 0.041456163 | E26: =Processing!G105 -> 146128
A27: • | B27: =Processing!E106 -> Service Charge | D27: =Processing!F106 -> 0.034017612 | E27: =Processing!G106 -> 119908
A28: • | B28: =Processing!E107 -> m-Soft | D28: =Processing!F107 -> 0.0086811466 | E28: =Processing!G107 -> 30600 | X28: Sales decision process is a formalized sales process companies use to manage the decision process behind a sale. SDP is a defined series of steps you follow as you guide prospects.
A29: • | B29: =Processing!E108 -> Business Applications | D29: =Processing!F108 -> 0.0075236604 | E29: =Processing!G108 -> 26520
B30: TOTAL | D30: =SUM(D16:D29) -> 1 | E30: =SUM(E16:E29) -> 3524880
X32: Distribution by Month

Sheet Cash Flow
B2: 🏠 DASHBOARD | U2: Cash Flow | X2: Working Capital | AA2: Sales Transactions
B8: General results of the movement of financial assets for all streams of sources of income of the enterprise for the selected accounting period. Visual analysis of the dominant sources of income in a certain period of the company's financial activity.
B13: TOTAL VALUE
B14: =Processing!B11 -> 3524880 | M14: =Processing!I27 -> Target Income
M15: =Processing!H28 -> 0.80447325
B22: Income Sources
B25: • | C25: Asset | D25: =Processing!C5 -> 0.15338848 | E25: =Processing!B5 -> 540676
B27: • | C27: Fees | D27: =Processing!C6 -> 0.034017612 | E27: =Processing!B6 -> 119908
B29: • | C29: Renting | D29: =Processing!C7 -> 0.17789769 | E29: =Processing!B7 -> 627068
B31: • | C31: Retail | D31: =Processing!C8 -> 0.26392728 | E31: =Processing!B8 -> 930312
B33: • | C33: Royalty | D33: =Processing!C9 -> 0.30041306 | E33: =Processing!B9 -> 1058920
B35: • | C35: SaaS | D35: =Processing!C10 -> 0.07035587 | E35: =Processing!B10 -> 247996

Sheet Working Capital
B2: 🏠 DASHBOARD | U2: Cash Flow | X2: Working Capital | AA2: Sales Transactions
B8: Working capital is a financial metric which represents operating liquidity available to a business, organization, or other entity, including governmental entities. Along with fixed assets such as plant and equipment, working capital is considered a part of operating capital.
B15: Sales Ranking by City
B18: • | C18: =Processing!E54 -> San Francisco | D18: =Processing!F54 -> 1028320 | E18: =Processing!G54 -> 0.29173192
B20: • | C20: =Processing!E55 -> Denver | D20: =Processing!F55 -> 627068 | E20: =Processing!G55 -> 0.17789769
B22: • | C22: =Processing!E56 -> Los Angeles | D22: =Processing!F56 -> 541004 | E22: =Processing!G56 -> 0.15348154
B24: • | C24: =Processing!E57 -> New York | D24: =Processing!F57 -> 540676 | E24: =Processing!G57 -> 0.15338848
B26: • | C26: =Processing!E58 -> Seattle | D26: =Processing!F58 -> 464656 | E26: =Processing!G58 -> 0.13182179
B28: • | C28: =Processing!E59 -> Dallas | D28: =Processing!F59 -> 266036 | E28: =Processing!G59 -> 0.075473775
B30: • | C30: =Processing!E60 -> Miami | D30: =Processing!F60 -> 30600 | E30: =Processing!G60 -> 0.0086811466 | Z30: =Processing!I27 -> Target Income
B32: • | C32: =Processing!E61 -> Chicago | D32: =Processing!F61 -> 26520 | E32: =Processing!G61 -> 0.0075236604 | Z32: =Processing!H28 -> 0.80447325
C34: TOTAL | D34: =SUM(D18:D32) -> 3524880 | E34: =SUM(E18:E32) -> 1

Sheet Sales Transactions
B2: 🏠 DASHBOARD | U2: Cash Flow | X2: Working Capital | AA2: Sales Transactions
B8: Is intended to design better ways of selling and make salespeople's efforts more productive. It has been described as "the systematic application of principles to achieve the practical goals of a particular sales process".

Sheet Processing
L1: Dia
L2: 1
L3: 1
A4: Row Labels | B4: Сумма по полю Income | C4: Сумма по полю Income2 | F4: X | G4: Y | H4: max | I4: Labels | L4: 1
A5: Asset | B5: 540676 | C5: 0.15338848 | D5: =A5 -> Asset | E5: =B5 -> 540676 | F5: 2 | G5: 8 | H5: =IF(E5=MAX($E$5:$E$10),E5,"") | I5: =IF(E5=MAX($E$5:$E$10),"",E5) -> 540676 | L5: 1
A6: Fees | B6: 119908 | C6: 0.034017612 | D6: =A6 -> Fees | E6: =B6 -> 119908 | F6: 4 | G6: 1 | H6: =IF(E6=MAX($E$5:$E$10),E6,"") | I6: =IF(E6=MAX($E$5:$E$10),"",E6) -> 119908 | L6: 1
A7: Renting | B7: 627068 | C7: 0.17789769 | D7: =A7 -> Renting | E7: =B7 -> 627068 | F7: 7 | G7: 2 | H7: =IF(E7=MAX($E$5:$E$10),E7,"") | I7: =IF(E7=MAX($E$5:$E$10),"",E7) -> 627068 | L7: 1
A8: Retail | B8: 930312 | C8: 0.26392728 | D8: =A8 -> Retail | E8: =B8 -> 930312 | F8: 6 | G8: 6 | H8: =IF(E8=MAX($E$5:$E$10),E8,"") | I8: =IF(E8=MAX($E$5:$E$10),"",E8) -> 930312 | L8: 1
A9: Royalty | B9: 1058920 | C9: 0.30041306 | D9: =A9 -> Royalty | E9: =B9 -> 1058920 | F9: 1 | G9: 3 | H9: =IF(E9=MAX($E$5:$E$10),E9,"") -> 1058920 | I9: =IF(E9=MAX($E$5:$E$10),"",E9) | L9: 1
A10: SaaS | B10: 247996 | C10: 0.07035587 | D10: =A10 -> SaaS | E10: =B10 -> 247996 | F10: 5 | G10: 9 | H10: =IF(E10=MAX($E$5:$E$10),E10,"") | I10: =IF(E10=MAX($E$5:$E$10),"",E10) -> 247996 | L10: 1
A11: Grand Total | B11: 3524880 | C11: 1 | L11: 1
L12: 1
L13: 1
A14: Row Labels | B14: Сумма по полю Income | C14: Сумма по полю Operating Profit | E14: Month | F14: Operating Profit | H14: Row Labels | I14: Сумма по полю Operating Profit | J14: Сумма по полю Operating Profit2 | L14: 1
A15: JAN | B15: 229242 | C15: 50148 | E15: =B15 -> 229242 | F15: =E15 -> 229242 | H15: B2B | I15: 234666 | J15: 0.38491164 | L15: 1
A16: FEB | B16: 251394 | C16: 59820 | E16: =B16 -> 251394 | F16: =E16 -> 251394 | H16: B2C | I16: 374996 | J16: 0.61508836 | L16: 1
A17: MAR | B17: 277566 | C17: 42980 | E17: =B17 -> 277566 | F17: =E17 -> 277566 | H17: Grand Total | I17: 609662 | J17: 1 | L17: 1
A18: APR | B18: 234942 | C18: 62920 | E18: =B18 -> 234942 | F18: =E18 -> 234942 | L18: 1
A19: MAY | B19: 294210 | C19: 52304 | E19: =B19 -> 294210 | F19: =E19 -> 294210 | L19: 1
A20: JUN | B20: 373754 | C20: 53792 | E20: =B20 -> 373754 | F20: =E20 -> 373754 | I20: B2B | J20: B2C | L20: 1
A21: JUL | B21: 333154 | C21: 67584 | E21: =B21 -> 333154 | F21: =E21 -> 333154 | I21: =J15 -> 0.38491164 | J21: =J16 -> 0.61508836 | L21: 1
A22: AUG | B22: 351242 | C22: 33212 | E22: =B22 -> 351242 | F22: =E22 -> 351242 | I22: =J15 -> 0.38491164 | J22: =J16 -> 0.61508836 | L22: 1
A23: SEP | B23: 267722 | C23: 40726 | E23: =B23 -> 267722 | F23: =E23 -> 267722 | I23: =I15 -> 234666 | J23: =I16 -> 374996 | L23: 1
A24: OCT | B24: 311710 | C24: 45700 | E24: =B24 -> 311710 | F24: =E24 -> 311710 | L24: 1
A25: NOV | B25: 307510 | C25: 54652 | E25: =B25 -> 307510 | F25: =E25 -> 307510 | H25: Сумма по полю Income | I25: Сумма по полю Target Income | L25: 1
A26: DEC | B26: 292434 | C26: 45824 | E26: =B26 -> 292434 | F26: =E26 -> 292434 | H26: 3524880 | I26: 4381600 | L26: 1
A27: Grand Total | B27: 3524880 | C27: 609662 | F27: Average | H27: Percentage | I27: Target Income | L27: 1
F28: =ROUND(AVERAGE(F15:F26),0) -> 293740 | H28: =H26/I26 -> 0.80447325 | I28: =IF(1-H28>=0,1-H28,0) -> 0.19552675 | L28: 1
H29: 100 | L29: 1
A30: Row Labels | B30: Сумма по полю Income | C30: Сумма по полю Income2 | H30: =IF(1-H28>=0,0,H28-1) -> 0 | I30: =1-H30 -> 1 | L30: 1
A31: Asset | B31: 540676 | C31: 0.15338848 | D31: =A31&CHAR(10)&TEXT(B31,"0 0") -> Asset 54067 6 | L31: 1
A32: Asset Sale | B32: 225676 | C32: 0.06402374 | D32: =A32&CHAR(10)&TEXT(B32,"0 0") -> Asset Sale 22567 6 | G32: Working Capital | J32: X | K32: Y | L32: 1
A33: Accounting Devices | B33: 315000 | C33: 0.089364744 | D33: =A33&CHAR(10)&TEXT(B33,"0 0") -> Accounting Devices 31500 0 | G33: =IF(H28>0.999,H28-1,0) -> 0 | H33: =IF(H28>0.999,1-G33,H28) -> 0.80447325 | I33: =IF(H28>0.999,0,I28) -> 0.19552675 | J33: 0 | K33: 1 | L33: 1
A34: Fees | B34: 119908 | C34: 0.034017612 | D34: =A34&CHAR(10)&TEXT(B34,"0 0") -> Fees 11990 8 | J34: =IF(H28>0.999,SIN(G33*2*PI()),SIN(H33*2*PI())) -> -0.94199672 | K34: =IF(H28>0.999,COS(H33*2*PI()),COS(I33*2*PI())) -> 0.33562208 | L34: 1
A35: Service Charge | B35: 119908 | C35: 0.034017612 | D35: =A35&CHAR(10)&TEXT(B35,"0 0") -> Service Charge 11990 8 | L35: 1
A36: Renting | B36: 627068 | C36: 0.17789769 | D36: =A36&CHAR(10)&TEXT(B36,"0 0") -> Renting 62706 8 | G36: Sales Process | J36: X | K36: Y | L36: 1
A37: Office rooms | B37: 311112 | C37: 0.088261728 | D37: =A37&CHAR(10)&TEXT(B37,"0 0") -> Office rooms 31111 2 | G37: =IF(H28>0.999,H28-1,0) -> 0 | H37: =IF(H28>0.999,1-G37,H28) -> 0.80447325 | I37: =IF(H28>0.999,0,I28) -> 0.19552675 | J37: 0 | K37: 1 | L37: 1
A38: Parking places | B38: 315956 | C38: 0.089635959 | D38: =A38&CHAR(10)&TEXT(B38,"0 0") -> Parking places 31595 6 | J38: =IF(H28>0.999,SIN(G33*2*PI()),SIN(H33*2*PI())) -> -0.94199672 | K38: =IF(H28>0.999,COS(H33*2*PI()),COS(I33*2*PI())) -> 0.33562208 | L38: 1
A39: Retail | B39: 930312 | C39: 0.26392728 | D39: =A39&CHAR(10)&TEXT(B39,"0 0") -> Retail 93031 2 | G39: Label 1 | H39: Label 2 | L39: 1
A40: Store | B40: 276876 | C40: 0.078549057 | D40: =A40&CHAR(10)&TEXT(B40,"0 0") -> Store 27687 6 | G40: =IF(H28>0.999,1,I28) -> 0.19552675 | H40: =IF(H28>0.999,"+"&TEXT(H28-1,"0%"),H28) -> 0.80447325 | L40: 1
...

Sheet Data
A1: Year | B1: Month | C1: Income Sources | D1: Income | E1: Income Breakdowns | F1: Orders | G1: Target Income | H1: Operating Profit | I1: Market Strategy | J1: City | K1: POS | L1: Payment Method | M1: Registration Status | N1: Refundented | O1: Customers | P1: https://exceltable.com/en/templates/
A2: 2021 | B2: JAN | C2: Asset | D2: 24028 | E2: Asset Sale | F2: 41 | G2: 60000 | H2: 1200 | I2: B2B | J2: New York | K2: Website | L2: Cash | M2: Registered | N2: 0.29 | O2: 41
A3: 2021 | B3: JAN | C3: Fees | D3: 15980 | E3: Service Charge | F3: 22 | G3: 30000 | H3: 900 | I3: B2B | J3: Dallas | K3: Shops | L3: Credit Card | M3: Registered | N3: 0.03 | O3: 20
A4: 2021 | B4: JAN | C4: Renting | D4: 62068 | E4: Office rooms | F4: 62 | G4: 80000 | H4: 3856 | I4: B2B | J4: Denver | K4: Shops | L4: Credit Card | M4: Registered | N4: 0.26 | O4: 62
A5: 2021 | B5: JAN | C5: Retail | D5: 7472 | E5: Store | F5: 62 | G5: 20000 | H5: 2612 | I5: B2C | J5: Los Angeles | K5: Shops | L5: Cash | M5: No-Registered | N5: 0.08 | O5: 62
A6: 2021 | B6: JAN | C6: Royalty | D6: 44967 | E6: Data Science Soft | F6: 75 | G6: 50000 | H6: 20 | I6: B2B | J6: Seattle | K6: Shops | L6: Cash | M6: Registered | N6: 0.09 | O6: 57
A7: 2021 | B7: JAN | C7: SaaS | D7: 668 | E7: CRM Software | F7: 47 | G7: 1000 | H7: 96 | I7: B2B | J7: San Francisco | K7: Website | L7: Credit Card | M7: Registered | N7: 0.17 | O7: 33
A8: 2021 | B8: JAN | C8: Retail | D8: 144 | E8: Business Applications | F8: 49 | G8: 1000 | H8: 44 | I8: B2C | J8: Chicago | K8: Shops | L8: Cash | M8: Registered | N8: 0.02 | O8: 40
A9: 2021 | B9: JAN | C9: Royalty | D9: 765 | E9: m-Soft | F9: 49 | G9: 5100 | H9: 224 | I9: B2B | J9: Miami | K9: Website | L9: Credit Card | M9: No-Registered | N9: 0.37 | O9: 35
A10: 2021 | B10: FEB | C10: Asset | D10: 268 | E10: Accounting Devices | F10: 51 | G10: 1000 | H10: 88 | I10: B2B | J10: New York | K10: Website | L10: Cash | M10: Registered | N10: 0.36 | O10: 36
A11: 2021 | B11: FEB | C11: Retail | D11: 216 | E11: Visualization Modules | F11: 31 | G11: 1000 | H11: 68 | I11: B2C | J11: New York | K11: Website | L11: Cash | M11: Registered | N11: 0.3 | O11: 22
A12: 2021 | B12: FEB | C12: Renting | D12: 9044 | E12: Parking places | F12: 31 | G12: 10000 | H12: 304 | I12: B2B | J12: Denver | K12: Shops | L12: Credit Card | M12: No-Registered | N12: 0.15 | O12: 23
A13: 2021 | B13: FEB | C13: Retail | D13: 240 | E13: Data Visualization Soft | F13: 22 | G13: 1000 | H13: 76 | I13: B2C | J13: Los Angeles | K13: Shops | L13: Credit Card | M13: No-Registered | N13: 0.22 | O13: 15
... A481: 2025 | B481: DEC | C481: Royalty | D481: 2550 | E481: m-Soft | F481: 21 | G481: 2473 | H481: 1020 | I481: B2B | J481: Miami | K481: Website | L481: Cash | M481: No-Registered | N481: 0.04 | O481: 19
